Workbook
Name WP_PLAN_S002_0_SOURCE_INDEX_ENTITY_NAME: '<.0> Source Index'!$B$2
Name WP_PLAN_S002_0_SOURCE_INDEX_FINANCIAL_STATEMENT_DATE: '<.0> Source Index'!$E$2
Name WP_PLAN_S002_0_SOURCE_INDEX_REPORTING_CURRENCY: '<.0> Source Index'!$H$2
Name WP_PLAN_S002_0_SOURCE_INDEX_PERFORMANCE_MATERIALITY: '<.0> Source Index'!$B$3
Name WP_PLAN_S002_0_SOURCE_INDEX_TOLERABLE_MISSTATEMENT: '<.0> Source Index'!$E$3
Name WP_PLAN_S003_1_AP_LEAD_SHEET_ENTITY_NAME: '<.1> AP Lead Sheet'!$B$2
Name WP_PLAN_S003_1_AP_LEAD_SHEET_FINANCIAL_STATEMENT_DATE: '<.1> AP Lead Sheet'!$E$2
Name WP_PLAN_S003_1_AP_LEAD_SHEET_REPORTING_CURRENCY: '<.1> AP Lead Sheet'!$H$2
Name WP_PLAN_S003_1_AP_LEAD_SHEET_PERFORMANCE_MATERIALITY: '<.1> AP Lead Sheet'!$B$3
Name WP_PLAN_S003_1_AP_LEAD_SHEET_TOLERABLE_MISSTATEMENT: '<.1> AP Lead Sheet'!$E$3
Name WP_PLAN_S004_2_AP_RECONCILIATION_ENTITY_NAME: '<.2> AP Reconciliation'!$B$2
Name WP_PLAN_S004_2_AP_RECONCILIATION_FINANCIAL_STATEMENT_DATE: '<.2> AP Reconciliation'!$E$2
Name WP_PLAN_S004_2_AP_RECONCILIATION_REPORTING_CURRENCY: '<.2> AP Reconciliation'!$H$2
Name WP_PLAN_S004_2_AP_RECONCILIATION_PERFORMANCE_MATERIALITY: '<.2> AP Reconciliation'!$B$3
Name WP_PLAN_S004_2_AP_RECONCILIATION_TOLERABLE_MISSTATEMENT: '<.2> AP Reconciliation'!$E$3
Name WP_PLAN_S005_3_DPO_SURL_POPULATION_ENTITY_NAME: '<.3> DPO & SURL Population'!$B$2
Name WP_PLAN_S005_3_DPO_SURL_POPULATION_FINANCIAL_STATEMENT_DATE: '<.3> DPO & SURL Population'!$E$2
Name WP_PLAN_S005_3_DPO_SURL_POPULATION_REPORTING_CURRENCY: '<.3> DPO & SURL Population'!$H$2
Name WP_PLAN_S005_3_DPO_SURL_POPULATION_PERFORMANCE_MATERIALITY: '<.3> DPO & SURL Population'!$B$3
Name WP_PLAN_S005_3_DPO_SURL_POPULATION_TOLERABLE_MISSTATEMENT: '<.3> DPO & SURL Population'!$E$3
Name WP_PLAN_S006_4_SURL_SUBSEQUENT_DISB_ENTITY_NAME: '<.4> SURL Subsequent Disb'!$B$2
Name WP_PLAN_S006_4_SURL_SUBSEQUENT_DISB_FINANCIAL_STATEMENT_DATE: '<.4> SURL Subsequent Disb'!$E$2
Name WP_PLAN_S006_4_SURL_SUBSEQUENT_DISB_REPORTING_CURRENCY: '<.4> SURL Subsequent Disb'!$H$2
Name WP_PLAN_S006_4_SURL_SUBSEQUENT_DISB_PERFORMANCE_MATERIALITY: '<.4> SURL Subsequent Disb'!$B$3
Name WP_PLAN_S006_4_SURL_SUBSEQUENT_DISB_TOLERABLE_MISSTATEMENT: '<.4> SURL Subsequent Disb'!$E$3
Name WP_PLAN_S007_5_COMPLETENESS_OF_DISB_ENTITY_NAME: '<.5> Completeness of Disb'!$B$2
Name WP_PLAN_S007_5_COMPLETENESS_OF_DISB_FINANCIAL_STATEMENT_DATE: '<.5> Completeness of Disb'!$E$2
Name WP_PLAN_S007_5_COMPLETENESS_OF_DISB_REPORTING_CURRENCY: '<.5> Completeness of Disb'!$H$2
Name WP_PLAN_S007_5_COMPLETENESS_OF_DISB_PERFORMANCE_MATERIALITY: '<.5> Completeness of Disb'!$B$3
Name WP_PLAN_S007_5_COMPLETENESS_OF_DISB_TOLERABLE_MISSTATEMENT: '<.5> Completeness of Disb'!$E$3
Name WP_PLAN_S008_6_OUTSTANDING_CHECKS_ENTITY_NAME: '<.6> Outstanding Checks'!$B$2
Name WP_PLAN_S008_6_OUTSTANDING_CHECKS_FINANCIAL_STATEMENT_DATE: '<.6> Outstanding Checks'!$E$2
Name WP_PLAN_S008_6_OUTSTANDING_CHECKS_REPORTING_CURRENCY: '<.6> Outstanding Checks'!$H$2
Name WP_PLAN_S008_6_OUTSTANDING_CHECKS_PERFORMANCE_MATERIALITY: '<.6> Outstanding Checks'!$B$3
Name WP_PLAN_S008_6_OUTSTANDING_CHECKS_TOLERABLE_MISSTATEMENT: '<.6> Outstanding Checks'!$E$3
Name WP_PLAN_S009_7_OPEN_INVOICE_CUTOFF_ENTITY_NAME: '<.7> Open Invoice & Cutoff'!$B$2
Name WP_PLAN_S009_7_OPEN_INVOICE_CUTOFF_FINANCIAL_STATEMENT_DATE: '<.7> Open Invoice & Cutoff'!$E$2
Name WP_PLAN_S009_7_OPEN_INVOICE_CUTOFF_REPORTING_CURRENCY: '<.7> Open Invoice & Cutoff'!$H$2
Name WP_PLAN_S009_7_OPEN_INVOICE_CUTOFF_PERFORMANCE_MATERIALITY: '<.7> Open Invoice & Cutoff'!$B$3
Name WP_PLAN_S009_7_OPEN_INVOICE_CUTOFF_TOLERABLE_MISSTATEMENT: '<.7> Open Invoice & Cutoff'!$E$3
Name WP_PLAN_S010_8_RATIOS_DISCLOSURES_ENTITY_NAME: '<.8> Ratios & Disclosures'!$B$2
Name WP_PLAN_S010_8_RATIOS_DISCLOSURES_FINANCIAL_STATEMENT_DATE: '<.8> Ratios & Disclosures'!$E$2
Name WP_PLAN_S010_8_RATIOS_DISCLOSURES_REPORTING_CURRENCY: '<.8> Ratios & Disclosures'!$H$2
Name WP_PLAN_S010_8_RATIOS_DISCLOSURES_PERFORMANCE_MATERIALITY: '<.8> Ratios & Disclosures'!$B$3
Name WP_PLAN_S010_8_RATIOS_DISCLOSURES_TOLERABLE_MISSTATEMENT: '<.8> Ratios & Disclosures'!$E$3
Name WP_PLAN_CONTEXT_ENTITY_NAME: 'Planning Context'!$B$3
Name WP_PLAN_CONTEXT_FINANCIAL_STATEMENT_DATE: 'Planning Context'!$B$4
Name WP_PLAN_CONTEXT_REPORTING_CURRENCY: 'Planning Context'!$B$5
Name WP_PLAN_CONTEXT_OVERALL_MATERIALITY: 'Planning Context'!$B$6
Name WP_PLAN_CONTEXT_PERFORMANCE_MATERIALITY: 'Planning Context'!$B$7
Name WP_PLAN_CONTEXT_TOLERABLE_MISSTATEMENT: 'Planning Context'!$B$8
Name WP_PLAN_CONTEXT_INDIVIDUALLY_SIGNIFICANT_THRESHOLD: 'Planning Context'!$B$9
Name WP_PLAN_CONTEXT_POSTING_THRESHOLD: 'Planning Context'!$B$10
Name WP_PLAN_CONTEXT_CLEARLY_TRIVIAL_THRESHOLD: 'Planning Context'!$B$11
Name WP_PLAN_CONTEXT_ANALYTICAL_PRECISION: 'Planning Context'!$B$12
Name WP_PROC_001_APPLICABILITY: 'Library Procedures'!$A$8
Name WP_PROC_001_REQUIREMENT: 'Library Procedures'!$B$8
Name WP_PROC_001_EXECUTION_STATE: 'Library Procedures'!$C$8
Name WP_PROC_001_EVIDENCE_STATE: 'Library Procedures'!$D$8
Name WP_PROC_001_RESULT_STATE: 'Library Procedures'!$E$8

Sheet Library Procedures
A1: Accounts Payable — Library of Audit Procedures
A2: Client / Entity: Vaquite Industries, Inc.
A3: Prepared by: Audit Senior 80A0 (assigned) Reviewed by: Audit Manager 403F (assigned)
A4: For every procedure, record applicability, requirement, execution, evidence, result, issue, and signoff states. Performed procedures require a W/P reference, preparer, date, result, and exact Evidence Index citation. Fact-driven N/A requires a FACT:/ JSON-Pointer citation and rationale; missing evidence remains Open. Preserve the assigned PROC: and WINDOW: dependency tokens.
A6: Applicability | B6: Requirement | C6: Execution state | D6: Evidence state | E6: Result state | F6: Issue state | G6: Signoff state | H6: Derived outcome | I6: Procedure | J6: Assertion(s) | K6: W/P Ref | L6: Performed by | M6: Date | N6: Reason code | O6: Source fact / evidence | P6: Issue / dependency IDs | Q6: Comment / Work performed
I7: <.0> Source Index
A8: Applicable | B8: Required | C8: Not Started | D8: Missing | E8: Unable to Conclude | F8: None | G8: Unsigned | H8: =IF(A8="Not Applicable - Fact Driven",IF(AND(C8="Not Performed",D8="Not Required",OR(F8="None",F8="Resolved",F8="Passed"),OR(G8="Prepared",G8="Reviewed"),LEFT(O8,6)="FACT:/",Q8<>""),"Valid N/A","Blocked"),IF(AND(B8="Recommended",C8="Not Performed",D8="Not Required",OR(F8="None",F8="Resolved",F8="Passed")),"Recommended - Not Performed",IF(C8<>"Performed","Open - "&C8,IF(D8<>"Sufficient","Open - "&D8&" Evidence",IF(E8="Unable to Conclude","Open - Unable to Conclude",IF(AND(E8="Exception Identified",ISERROR(SEARCH("ISSUE:",P8))),"Open - Missing Issue ID",IF(AND(F8="Open",ISERROR(SEARCH("ISSUE:",P8))),"Open - Missing Issue ID",IF(OR(F8="Open",F8="Superseded"),"Open - "&F8&" Issue",IF(AND(E8="Exception Identified",NOT(OR(F8="Adjusted",F8="Passed",F8="Resolved"))),"Open - Undispositioned Exception",IF(OR(G8="Prepared",G8="Reviewed"),"Passed","Open - Unsigned")))))))))) | I8: 1. Obtain and index all AP PBC sources (trade-only AP aging/sub-ledger, GL detail, subsequent disbursement records / bank statements, open/unpaid invoice file, vendor statements, RNI / unmatched-receiving report); document limitations. | J8: Completeness | K8: <.0> | P8: PROC:PROC-AP-AND-ACCRUALS; WINDOW:WIN-AP-SURL
I9: <.1> AP Lead Sheet
A10: Applicable | B10: Required | C10: Not Started | D10: Missing | E10: Unable to Conclude | F10: None | G10: Unsigned | H10: =IF(A10="Not Applicable - Fact Driven",IF(AND(C10="Not Performed",D10="Not Required",OR(F10="None",F10="Resolved",F10="Passed"),OR(G10="Prepared",G10="Reviewed"),LEFT(O10,6)="FACT:/",Q10<>""),"Valid N/A","Blocked"),IF(AND(B10="Recommended",C10="Not Performed",D10="Not Required",OR(F10="None",F10="Resolved",F10="Passed")),"Recommended - Not Performed",IF(C10<>"Performed","Open - "&C10,IF(D10<>"Sufficient","Open - "&D10&" Evidence",IF(E10="Unable to Conclude","Open - Unable to Conclude",IF(AND(E10="Exception Identified",ISERROR(SEARCH("ISSUE:",P10))),"Open - Missing Issue ID",IF(AND(F10="Open",ISERROR(SEARCH("ISSUE:",P10))),"Open - Missing Issue ID",IF(OR(F10="Open",F10="Superseded"),"Open - "&F10&" Issue",IF(AND(E10="Exception Identified",NOT(OR(F10="Adjusted",F10="Passed",F10="Resolved"))),"Open - Undispositioned Exception",IF(OR(G10="Prepared",G10="Reviewed"),"Passed","Open - Unsigned")))))))))) | I10: 2. Obtain the AP lead sheet and agree each CY and PY trade-payable balance to the trial balance and general ledger; state the sign convention (positive payable magnitudes). | J10: Completeness; Existence | K10: <.1> | P10: PROC:PROC-AP-AND-ACCRUALS
A11: Applicable | B11: Required | C11: Not Started | D11: Missing | E11: Unable to Conclude | F11: None | G11: Unsigned | H11: =IF(A11="Not Applicable - Fact Driven",IF(AND(C11="Not Performed",D11="Not Required",OR(F11="None",F11="Resolved",F11="Passed"),OR(G11="Prepared",G11="Reviewed"),LEFT(O11,6)="FACT:/",Q11<>""),"Valid N/A","Blocked"),IF(AND(B11="Recommended",C11="Not Performed",D11="Not Required",OR(F11="None",F11="Resolved",F11="Passed")),"Recommended - Not Performed",IF(C11<>"Performed","Open - "&C11,IF(D11<>"Sufficient","Open - "&D11&" Evidence",IF(E11="Unable to Conclude","Open - Unable to Conclude",IF(AND(E11="Exception Identified",ISERROR(SEARCH("ISSUE:",P11))),"Open - Missing Issue ID",IF(AND(F11="Open",ISERROR(SEARCH("ISSUE:",P11))),"Open - Missing Issue ID",IF(OR(F11="Open",F11="Superseded"),"Open - "&F11&" Issue",IF(AND(E11="Exception Identified",NOT(OR(F11="Adjusted",F11="Passed",F11="Resolved"))),"Open - Undispositioned Exception",IF(OR(G11="Prepared",G11="Reviewed"),"Passed","Open - Unsigned")))))))))) | I11: 3. Foot the lead sheet and agree CY and PY totals to the trial balance. | J11: Accuracy | K11: <.1> | P11: PROC:PROC-AP-AND-ACCRUALS
A12: Applicable | B12: Required | C12: Not Started | D12: Missing | E12: Unable to Conclude | F12: None | G12: Unsigned | H12: =IF(A12="Not Applicable - Fact Driven",IF(AND(C12="Not Performed",D12="Not Required",OR(F12="None",F12="Resolved",F12="Passed"),OR(G12="Prepared",G12="Reviewed"),LEFT(O12,6)="FACT:/",Q12<>""),"Valid N/A","Blocked"),IF(AND(B12="Recommended",C12="Not Performed",D12="Not Required",OR(F12="None",F12="Resolved",F12="Passed")),"Recommended - Not Performed",IF(C12<>"Performed","Open - "&C12,IF(D12<>"Sufficient","Open - "&D12&" Evidence",IF(E12="Unable to Conclude","Open - Unable to Conclude",IF(AND(E12="Exception Identified",ISERROR(SEARCH("ISSUE:",P12))),"Open - Missing Issue ID",IF(AND(F12="Open",ISERROR(SEARCH("ISSUE:",P12))),"Open - Missing Issue ID",IF(OR(F12="Open",F12="Superseded"),"Open - "&F12&" Issue",IF(AND(E12="Exception Identified",NOT(OR(F12="Adjusted",F12="Passed",F12="Resolved"))),"Open - Undispositioned Exception",IF(OR(G12="Prepared",G12="Reviewed"),"Passed","Open - Unsigned")))))))))) | I12: 4. Confirm the population is trade payables only — separate non-trade items miscoded into the AP aging (e.g. accrued payroll, customer deposits) and investigate debit balances for reclassification to other assets. | J12: Classification; Completeness | K12: <.1> | P12: PROC:PROC-AP-AND-ACCRUALS
I13: <.2> AP Reconciliation
A14: Applicable | B14: Required | C14: Not Started | D14: Missing | E14: Unable to Conclude | F14: None | G14: Unsigned | H14: =IF(A14="Not Applicable - Fact Driven",IF(AND(C14="Not Performed",D14="Not Required",OR(F14="None",F14="Resolved",F14="Passed"),OR(G14="Prepared",G14="Reviewed"),LEFT(O14,6)="FACT:/",Q14<>""),"Valid N/A","Blocked"),IF(AND(B14="Recommended",C14="Not Performed",D14="Not Required",OR(F14="None",F14="Resolved",F14="Passed")),"Recommended - Not Performed",IF(C14<>"Performed","Open - "&C14,IF(D14<>"Sufficient","Open - "&D14&" Evidence",IF(E14="Unable to Conclude","Open - Unable to Conclude",IF(AND(E14="Exception Identified",ISERROR(SEARCH("ISSUE:",P14))),"Open - Missing Issue ID",IF(AND(F14="Open",ISERROR(SEARCH("ISSUE:",P14))),"Open - Missing Issue ID",IF(OR(F14="Open",F14="Superseded"),"Open - "&F14&" Issue",IF(AND(E14="Exception Identified",NOT(OR(F14="Adjusted",F14="Passed",F14="Resolved"))),"Open - Undispositioned Exception",IF(OR(G14="Prepared",G14="Reviewed"),"Passed","Open - Unsigned")))))))))) | I14: 5. Reconcile the AP sub-ledger / aging to the general ledger and trial balance; investigate reconciling items. | J14: Completeness; Accuracy | K14: <.2> | O14: AP-01 — AP-to-GL Reconciliation | P14: PROC:PROC-AP-AND-ACCRUALS; PBC:AP-01-RECONCILIATION
A15: Applicable | B15: Required | C15: Not Started | D15: Missing | E15: Unable to Conclude | F15: None | G15: Unsigned | H15: =IF(A15="Not Applicable - Fact Driven",IF(AND(C15="Not Performed",D15="Not Required",OR(F15="None",F15="Resolved",F15="Passed"),OR(G15="Prepared",G15="Reviewed"),LEFT(O15,6)="FACT:/",Q15<>""),"Valid N/A","Blocked"),IF(AND(B15="Recommended",C15="Not Performed",D15="Not Required",OR(F15="None",F15="Resolved",F15="Passed")),"Recommended - Not Performed",IF(C15<>"Performed","Open - "&C15,IF(D15<>"Sufficient","Open - "&D15&" Evidence",IF(E15="Unable to Conclude","Open - Unable to Conclude",IF(AND(E15="Exception Identified",ISERROR(SEARCH("ISSUE:",P15))),"Open - Missing Issue ID",IF(AND(F15="Open",ISERROR(SEARCH("ISSUE:",P15))),"Open - Missing Issue ID",IF(OR(F15="Open",F15="Superseded"),"Open - "&F15&" Issue",IF(AND(E15="Exception Identified",NOT(OR(F15="Adjusted",F15="Passed",F15="Resolved"))),"Open - Undispositioned Exception",IF(OR(G15="Prepared",G15="Reviewed"),"Passed","Open - Unsigned")))))))))) | I15: 6. Obtain vendor statements for major vendors and reconcile to the AP sub-ledger; resolve in-transit invoices/payments and differences. | J15: Completeness; Existence | K15: <.2> | O15: AP Controls — vendor statement scope | P15: PROC:PROC-AP-AND-ACCRUALS; APCTRL:Vendor reference Statement Scope
I16: <.3> DPO & SURL Population
A17: Applicable | B17: Required | C17: Not Started | D17: Missing | E17: Unable to Conclude | F17: None | G17: Unsigned | H17: =IF(A17="Not Applicable - Fact Driven",IF(AND(C17="Not Performed",D17="Not Required",OR(F17="None",F17="Resolved",F17="Passed"),OR(G17="Prepared",G17="Reviewed"),LEFT(O17,6)="FACT:/",Q17<>""),"Valid N/A","Blocked"),IF(AND(B17="Recommended",C17="Not Performed",D17="Not Required",OR(F17="None",F17="Resolved",F17="Passed")),"Recommended - Not Performed",IF(C17<>"Performed","Open - "&C17,IF(D17<>"Sufficient","Open - "&D17&" Evidence",IF(E17="Unable to Conclude","Open - Unable to Conclude",IF(AND(E17="Exception Identified",ISERROR(SEARCH("ISSUE:",P17))),"Open - Missing Issue ID",IF(AND(F17="Open",ISERROR(SEARCH("ISSUE:",P17))),"Open - Missing Issue ID",IF(OR(F17="Open",F17="Superseded"),"Open - "&F17&" Issue",IF(AND(E17="Exception Identified",NOT(OR(F17="Adjusted",F17="Passed",F17="Resolved"))),"Open - Undispositioned Exception",IF(OR(G17="Prepared",G17="Reviewed"),"Passed","Open - Unsigned")))))))))) | I17: 7. Compute Days Payable Outstanding (DPO = 365 / AP turnover) and set the SURL look-forward period as period-end through period-end + DPO. | J17: Completeness; Cutoff | K17: <.3> | O17: AP Controls — typed metric/SURL section | P17: PROC:PROC-AP-AND-ACCRUALS; WINDOW:WIN-AP-SURL; APCTRL:SURL-WINDOW
A18: Applicable | B18: Required | C18: Not Started | D18: Missing | E18: Unable to Conclude | F18: None | G18: Unsigned | H18: =IF(A18="Not Applicable - Fact Driven",IF(AND(C18="Not Performed",D18="Not Required",OR(F18="None",F18="Resolved",F18="Passed"),OR(G18="Prepared",G18="Reviewed"),LEFT(O18,6)="FACT:/",Q18<>""),"Valid N/A","Blocked"),IF(AND(B18="Recommended",C18="Not Performed",D18="Not Required",OR(F18="None",F18="Resolved",F18="Passed")),"Recommended - Not Performed",IF(C18<>"Performed","Open - "&C18,IF(D18<>"Sufficient","Open - "&D18&" Evidence",IF(E18="Unable to Conclude","Open - Unable to Conclude",IF(AND(E18="Exception Identified",ISERROR(SEARCH("ISSUE:",P18))),"Open - Missing Issue ID",IF(AND(F18="Open",ISERROR(SEARCH("ISSUE:",P18))),"Open - Missing Issue ID",IF(OR(F18="Open",F18="Superseded"),"Open - "&F18&" Issue",IF(AND(E18="Exception Identified",NOT(OR(F18="Adjusted",F18="Passed",F18="Resolved"))),"Open - Undispositioned Exception",IF(OR(G18="Prepared",G18="Reviewed"),"Passed","Open - Unsigned")))))))))) | I18: 8. Quantify the subsequent-disbursement population (checks, ACH, wires, credit cards) from which SURL selections will be drawn. | J18: Completeness | K18: <.3> | O18: AP Controls — typed metric/SURL section; AP-04 — Bank Debit Control | P18: PROC:PROC-AP-AND-ACCRUALS; WINDOW:WIN-AP-SURL; APCTRL:SURL-WINDOW; PBC:AP-04-Bank account Debit Control
I19: <.4> SURL — Subsequent Disbursements
A20: Applicable | B20: Required | C20: Not Started | D20: Missing | E20: Unable to Conclude | F20: None | G20: Unsigned | H20: =IF(A20="Not Applicable - Fact Driven",IF(AND(C20="Not Performed",D20="Not Required",OR(F20="None",F20="Resolved",F20="Passed"),OR(G20="Prepared",G20="Reviewed"),LEFT(O20,6)="FACT:/",Q20<>""),"Valid N/A","Blocked"),IF(AND(B20="Recommended",C20="Not Performed",D20="Not Required",OR(F20="None",F20="Resolved",F20="Passed")),"Recommended - Not Performed",IF(C20<>"Performed","Open - "&C20,IF(D20<>"Sufficient","Open - "&D20&" Evidence",IF(E20="Unable to Conclude","Open - Unable to Conclude",IF(AND(E20="Exception Identified",ISERROR(SEARCH("ISSUE:",P20))),"Open - Missing Issue ID",IF(AND(F20="Open",ISERROR(SEARCH("ISSUE:",P20))),"Open - Missing Issue ID",IF(OR(F20="Open",F20="Superseded"),"Open - "&F20&" Issue",IF(AND(E20="Exception Identified",NOT(OR(F20="Adjusted",F20="Passed",F20="Resolved"))),"Open - Undispositioned Exception",IF(OR(G20="Prepared",G20="Reviewed"),"Passed","Open - Unsigned")))))))))) | I20: 9. Perform a search for unrecorded liabilities — examine subsequent disbursements above the testing threshold through the SURL period; vouch to invoice and determine the goods-received / service period. | J20: Completeness; Cutoff | K20: <.4> | O20: AP Controls — selection reconciliation | P20: PROC:PROC-AP-AND-ACCRUALS; WINDOW:WIN-AP-SURL; APCTRL:REGISTERED-SELECTIONS
A21: Applicable | B21: Required | C21: Not Started | D21: Missing | E21: Unable to Conclude | F21: None | G21: Unsigned | H21: =IF(A21="Not Applicable - Fact Driven",IF(AND(C21="Not Performed",D21="Not Required",OR(F21="None",F21="Resolved",F21="Passed"),OR(G21="Prepared",G21="Reviewed"),LEFT(O21,6)="FACT:/",Q21<>""),"Valid N/A","Blocked"),IF(AND(B21="Recommended",C21="Not Performed",D21="Not Required",OR(F21="None",F21="Resolved",F21="Passed")),"Recommended - Not Performed",IF(C21<>"Performed","Open - "&C21,IF(D21<>"Sufficient","Open - "&D21&" Evidence",IF(E21="Unable to Conclude","Open - Unable to Conclude",IF(AND(E21="Exception Identified",ISERROR(SEARCH("ISSUE:",P21))),"Open - Missing Issue ID",IF(AND(F21="Open",ISERROR(SEARCH("ISSUE:",P21))),"Open - Missing Issue ID",IF(OR(F21="Open",F21="Superseded"),"Open - "&F21&" Issue",IF(AND(E21="Exception Identified",NOT(OR(F21="Adjusted",F21="Passed",F21="Resolved"))),"Open - Undispositioned Exception",IF(OR(G21="Prepared",G21="Reviewed"),"Passed","Open - Unsigned")))))))))) | I21: 10. Classify each item at period end — properly included, properly excluded, improperly included, or improperly excluded (an unrecorded liability); for pre-year-end items tie back to year-end AP, and for post-year-end items confirm exclusion from year-end AP. | J21: Completeness; Cutoff; Valuation & Allocation | K21: <.4> | O21: AP Controls — selection reconciliation | P21: PROC:PROC-AP-AND-ACCRUALS; APCTRL:REGISTERED-SELECTIONS
I22: <.5> Completeness of Disbursements
A23: Applicable | B23: Required | C23: Not Started | D23: Missing | E23: Unable to Conclude | F23: None | G23: Unsigned | H23: =IF(A23="Not Applicable - Fact Driven",IF(AND(C23="Not Performed",D23="Not Required",OR(F23="None",F23="Resolved",F23="Passed"),OR(G23="Prepared",G23="Reviewed"),LEFT(O23,6)="FACT:/",Q23<>""),"Valid N/A","Blocked"),IF(AND(B23="Recommended",C23="Not Performed",D23="Not Required",OR(F23="None",F23="Resolved",F23="Passed")),"Recommended - Not Performed",IF(C23<>"Performed","Open - "&C23,IF(D23<>"Sufficient","Open - "&D23&" Evidence",IF(E23="Unable to Conclude","Open - Unable to Conclude",IF(AND(E23="Exception Identified",ISERROR(SEARCH("ISSUE:",P23))),"Open - Missing Issue ID",IF(AND(F23="Open",ISERROR(SEARCH("ISSUE:",P23))),"Open - Missing Issue ID",IF(OR(F23="Open",F23="Superseded"),"Open - "&F23&" Issue",IF(AND(E23="Exception Identified",NOT(OR(F23="Adjusted",F23="Passed",F23="Resolved"))),"Open - Undispositioned Exception",IF(OR(G23="Prepared",G23="Reviewed"),"Passed","Open - Unsigned")))))))))) | I23: 11. Where SURL selections were drawn from the disbursement listing, test the completeness of that population — perform a sequence check of payment/check document numbers and agree the listing to the subsequent-period bank statement. | J23: Completeness | K23: <.5> | P23: PROC:PROC-AP-AND-ACCRUALS; WINDOW:WIN-AP-SURL
A24: Applicable | B24: Required | C24: Not Started | D24: Missing | E24: Unable to Conclude | F24: None | G24: Unsigned | H24: =IF(A24="Not Applicable - Fact Driven",IF(AND(C24="Not Performed",D24="Not Required",OR(F24="None",F24="Resolved",F24="Passed"),OR(G24="Prepared",G24="Reviewed"),LEFT(O24,6)="FACT:/",Q24<>""),"Valid N/A","Blocked"),IF(AND(B24="Recommended",C24="Not Performed",D24="Not Required",OR(F24="None",F24="Resolved",F24="Passed")),"Recommended - Not Performed",IF(C24<>"Performed","Open - "&C24,IF(D24<>"Sufficient","Open - "&D24&" Evidence",IF(E24="Unable to Conclude","Open - Unable to Conclude",IF(AND(E24="Exception Identified",ISERROR(SEARCH("ISSUE:",P24))),"Open - Missing Issue ID",IF(AND(F24="Open",ISERROR(SEARCH("ISSUE:",P24))),"Open - Missing Issue ID",IF(OR(F24="Open",F24="Superseded"),"Open - "&F24&" Issue",IF(AND(E24="Exception Identified",NOT(OR(F24="Adjusted",F24="Passed",F24="Resolved"))),"Open - Undispositioned Exception",IF(OR(G24="Prepared",G24="Reviewed"),"Passed","Open - Unsigned")))))))))) | I24: 12. Where SURL selections were drawn directly from the bank statement, document that the completeness test of the disbursement listing is NOT required (the bank statement is inherently complete). | J24: Completeness | K24: <.5> | P24: PROC:PROC-AP-AND-ACCRUALS; WINDOW:WIN-AP-SURL
I25: <.6> Outstanding Checks → AP Tie-Back
A26: Applicable | B26: Required | C26: Not Started | D26: Missing | E26: Unable to Conclude | F26: None | G26: Unsigned | H26: =IF(A26="Not Applicable - Fact Driven",IF(AND(C26="Not Performed",D26="Not Required",OR(F26="None",F26="Resolved",F26="Passed"),OR(G26="Prepared",G26="Reviewed"),LEFT(O26,6)="FACT:/",Q26<>""),"Valid N/A","Blocked"),IF(AND(B26="Recommended",C26="Not Performed",D26="Not Required",OR(F26="None",F26="Resolved",F26="Passed")),"Recommended - Not Performed",IF(C26<>"Performed","Open - "&C26,IF(D26<>"Sufficient","Open - "&D26&" Evidence",IF(E26="Unable to Conclude","Open - Unable to Conclude",IF(AND(E26="Exception Identified",ISERROR(SEARCH("ISSUE:",P26))),"Open - Missing Issue ID",IF(AND(F26="Open",ISERROR(SEARCH("ISSUE:",P26))),"Open - Missing Issue ID",IF(OR(F26="Open",F26="Superseded"),"Open - "&F26&" Issue",IF(AND(E26="Exception Identified",NOT(OR(F26="Adjusted",F26="Passed",F26="Resolved"))),"Open - Undispositioned Exception",IF(OR(G26="Prepared",G26="Reviewed"),"Passed","Open - Unsigned")))))))))) | I26: 13. Select outstanding checks issued on or before period-end that had not cleared the bank, and tie each back to the AP listing to confirm the related payable is appropriately recorded. | J26: Completeness; Existence | K26: <.6> | O26: AP-04 — Outstanding Check AP Relief | P26: PROC:PROC-AP-AND-ACCRUALS; PBC:AP-04-OUTSTANDING-CHECK-RELIEF
I27: <.7> Open / Unpaid Invoice & Cutoff
A28: Applicable | B28: Required | C28: Not Started | D28: Missing | E28: Unable to Conclude | F28: None | G28: Unsigned | H28: =IF(A28="Not Applicable - Fact Driven",IF(AND(C28="Not Performed",D28="Not Required",OR(F28="None",F28="Resolved",F28="Passed"),OR(G28="Prepared",G28="Reviewed"),LEFT(O28,6)="FACT:/",Q28<>""),"Valid N/A","Blocked"),IF(AND(B28="Recommended",C28="Not Performed",D28="Not Required",OR(F28="None",F28="Resolved",F28="Passed")),"Recommended - Not Performed",IF(C28<>"Performed","Open - "&C28,IF(D28<>"Sufficient","Open - "&D28&" Evidence",IF(E28="Unable to Conclude","Open - Unable to Conclude",IF(AND(E28="Exception Identified",ISERROR(SEARCH("ISSUE:",P28))),"Open - Missing Issue ID",IF(AND(F28="Open",ISERROR(SEARCH("ISSUE:",P28))),"Open - Missing Issue ID",IF(OR(F28="Open",F28="Superseded"),"Open - "&F28&" Issue",IF(AND(E28="Exception Identified",NOT(OR(F28="Adjusted",F28="Passed",F28="Resolved"))),"Open - Undispositioned Exception",IF(OR(G28="Prepared",G28="Reviewed"),"Passed","Open - Unsigned")))))))))) | I28: 14. Select unpaid / open invoices from the subsequent period; determine the goods-received / service period; if it relates to pre-year-end, trace into year-end AP (an unrecorded liability if omitted); if post-year-end, confirm it is excluded from year-end AP. | J28: Completeness; Existence; Cutoff | K28: <.7> | O28: AP Controls — selection reconciliation | P28: PROC:PROC-AP-AND-ACCRUALS; WINDOW:WIN-AP-SURL; APCTRL:REGISTERED-SELECTIONS
A29: Applicable | B29: Required | C29: Not Started | D29: Missing | E29: Unable to Conclude | F29: None | G29: Unsigned | H29: =IF(A29="Not Applicable - Fact Driven",IF(AND(C29="Not Performed",D29="Not Required",OR(F29="None",F29="Resolved",F29="Passed"),OR(G29="Prepared",G29="Reviewed"),LEFT(O29,6)="FACT:/",Q29<>""),"Valid N/A","Blocked"),IF(AND(B29="Recommended",C29="Not Performed",D29="Not Required",OR(F29="None",F29="Resolved",F29="Passed")),"Recommended - Not Performed",IF(C29<>"Performed","Open - "&C29,IF(D29<>"Sufficient","Open - "&D29&" Evidence",IF(E29="Unable to Conclude","Open - Unable to Conclude",IF(AND(E29="Exception Identified",ISERROR(SEARCH("ISSUE:",P29))),"Open - Missing Issue ID",IF(AND(F29="Open",ISERROR(SEARCH("ISSUE:",P29))),"Open - Missing Issue ID",IF(OR(F29="Open",F29="Superseded"),"Open - "&F29&" Issue",IF(AND(E29="Exception Identified",NOT(OR(F29="Adjusted",F29="Passed",F29="Resolved"))),"Open - Undispositioned Exception",IF(OR(G29="Prepared",G29="Reviewed"),"Passed","Open - Unsigned")))))))))) | I29: 15. Obtain the received-not-invoiced (RNI) / unmatched-receiving report and test completeness of accrued purchases. | J29: Completeness | K29: <.7> | O29: AP-06 — Population Controls/RNI Exceptions; accrued-expense RNI disposition | P29: PROC:PROC-AP-AND-ACCRUALS; PBC:AP-06-Received-not-invoiced reference Control; ACCRUAL:Received-not-invoiced reference Disposition
I30: <.8> Ratios & Disclosures
A31: Applicable | B31: Required | C31: Not Started | D31: Missing | E31: Unable to Conclude | F31: None | G31: Unsigned | H31: =IF(A31="Not Applicable - Fact Driven",IF(AND(C31="Not Performed",D31="Not Required",OR(F31="None",F31="Resolved",F31="Passed"),OR(G31="Prepared",G31="Reviewed"),LEFT(O31,6)="FACT:/",Q31<>""),"Valid N/A","Blocked"),IF(AND(B31="Recommended",C31="Not Performed",D31="Not Required",OR(F31="None",F31="Resolved",F31="Passed")),"Recommended - Not Performed",IF(C31<>"Performed","Open - "&C31,IF(D31<>"Sufficient","Open - "&D31&" Evidence",IF(E31="Unable to Conclude","Open - Unable to Conclude",IF(AND(E31="Exception Identified",ISERROR(SEARCH("ISSUE:",P31))),"Open - Missing Issue ID",IF(AND(F31="Open",ISERROR(SEARCH("ISSUE:",P31))),"Open - Missing Issue ID",IF(OR(F31="Open",F31="Superseded"),"Open - "&F31&" Issue",IF(AND(E31="Exception Identified",NOT(OR(F31="Adjusted",F31="Passed",F31="Resolved"))),"Open - Undispositioned Exception",IF(OR(G31="Prepared",G31="Reviewed"),"Passed","Open - Unsigned")))))))))) | I31: 16. Compute AP analytics (DPO, AP turnover, AP as % of COGS/expenses) and investigate unusual trends. | J31: Presentation & Disclosure | K31: <.8> | O31: AP Controls — typed metric/SURL section | P31: PROC:PROC-AP-AND-ACCRUALS; APCTRL:TYPED-METRICS
A32: Applicable | B32: Required | C32: Not Started | D32: Missing | E32: Unable to Conclude | F32: None | G32: Unsigned | H32: =IF(A32="Not Applicable - Fact Driven",IF(AND(C32="Not Performed",D32="Not Required",OR(F32="None",F32="Resolved",F32="Passed"),OR(G32="Prepared",G32="Reviewed"),LEFT(O32,6)="FACT:/",Q32<>""),"Valid N/A","Blocked"),IF(AND(B32="Recommended",C32="Not Performed",D32="Not Required",OR(F32="None",F32="Resolved",F32="Passed")),"Recommended - Not Performed",IF(C32<>"Performed","Open - "&C32,IF(D32<>"Sufficient","Open - "&D32&" Evidence",IF(E32="Unable to Conclude","Open - Unable to Conclude",IF(AND(E32="Exception Identified",ISERROR(SEARCH("ISSUE:",P32))),"Open - Missing Issue ID",IF(AND(F32="Open",ISERROR(SEARCH("ISSUE:",P32))),"Open - Missing Issue ID",IF(OR(F32="Open",F32="Superseded"),"Open - "&F32&" Issue",IF(AND(E32="Exception Identified",NOT(OR(F32="Adjusted",F32="Passed",F32="Resolved"))),"Open - Undispositioned Exception",IF(OR(G32="Prepared",G32="Reviewed"),"Passed","Open - Unsigned")))))))))) | I32: 17. Evaluate AP presentation and disclosure — related-party payables, current vs noncurrent, debit balances reclassified, customer deposits / contract-liability classification, and concentration. | J32: Presentation & Disclosure; Classification | K32: <.8> | P32: PROC:PROC-AP-AND-ACCRUALS
A33: Applicable | B33: Required | C33: Not Started | D33: Missing | E33: Unable to Conclude | F33: None | G33: Unsigned | H33: =IF(A33="Not Applicable - Fact Driven",IF(AND(C33="Not Performed",D33="Not Required",OR(F33="None",F33="Resolved",F33="Passed"),OR(G33="Prepared",G33="Reviewed"),LEFT(O33,6)="FACT:/",Q33<>""),"Valid N/A","Blocked"),IF(AND(B33="Recommended",C33="Not Performed",D33="Not Required",OR(F33="None",F33="Resolved",F33="Passed")),"Recommended - Not Performed",IF(C33<>"Performed","Open - "&C33,IF(D33<>"Sufficient","Open - "&D33&" Evidence",IF(E33="Unable to Conclude","Open - Unable to Conclude",IF(AND(E33="Exception Identified",ISERROR(SEARCH("ISSUE:",P33))),"Open - Missing Issue ID",IF(AND(F33="Open",ISERROR(SEARCH("ISSUE:",P33))),"Open - Missing Issue ID",IF(OR(F33="Open",F33="Superseded"),"Open - "&F33&" Issue",IF(AND(E33="Exception Identified",NOT(OR(F33="Adjusted",F33="Passed",F33="Resolved"))),"Open - Undispositioned Exception",IF(OR(G33="Prepared",G33="Reviewed"),"Passed","Open - Unsigned")))))))))) | I33: 18. Inquire of management and review board minutes / legal letters for unrecorded obligations, commitments and purchase obligations. | J33: Completeness; Presentation & Disclosure | K33: <.8> | P33: PROC:PROC-AP-AND-ACCRUALS
I34: Documentation & Review
A35: Applicable | B35: Required | C35: Not Started | D35: Missing | E35: Unable to Conclude | F35: None | G35: Unsigned | H35: =IF(A35="Not Applicable - Fact Driven",IF(AND(C35="Not Performed",D35="Not Required",OR(F35="None",F35="Resolved",F35="Passed"),OR(G35="Prepared",G35="Reviewed"),LEFT(O35,6)="FACT:/",Q35<>""),"Valid N/A","Blocked"),IF(AND(B35="Recommended",C35="Not Performed",D35="Not Required",OR(F35="None",F35="Resolved",F35="Passed")),"Recommended - Not Performed",IF(C35<>"Performed","Open - "&C35,IF(D35<>"Sufficient","Open - "&D35&" Evidence",IF(E35="Unable to Conclude","Open - Unable to Conclude",IF(AND(E35="Exception Identified",ISERROR(SEARCH("ISSUE:",P35))),"Open - Missing Issue ID",IF(AND(F35="Open",ISERROR(SEARCH("ISSUE:",P35))),"Open - Missing Issue ID",IF(OR(F35="Open",F35="Superseded"),"Open - "&F35&" Issue",IF(AND(E35="Exception Identified",NOT(OR(F35="Adjusted",F35="Passed",F35="Resolved"))),"Open - Undispositioned Exception",IF(OR(G35="Prepared",G35="Reviewed"),"Passed","Open - Unsigned")))))))))) | I35: 19. Cross-reference each procedure to its workpaper tab and link it to the relevant assertion(s). | J35: Overall | K35: <.0>-<.8> | P35: PROC:PROC-AP-AND-ACCRUALS
A36: Applicable | B36: Required | C36: Not Started | D36: Missing | E36: Unable to Conclude | F36: None | G36: Unsigned | H36: =IF(A36="Not Applicable - Fact Driven",IF(AND(C36="Not Performed",D36="Not Required",OR(F36="None",F36="Resolved",F36="Passed"),OR(G36="Prepared",G36="Reviewed"),LEFT(O36,6)="FACT:/",Q36<>""),"Valid N/A","Blocked"),IF(AND(B36="Recommended",C36="Not Performed",D36="Not Required",OR(F36="None",F36="Resolved",F36="Passed")),"Recommended - Not Performed",IF(C36<>"Performed","Open - "&C36,IF(D36<>"Sufficient","Open - "&D36&" Evidence",IF(E36="Unable to Conclude","Open - Unable to Conclude",IF(AND(E36="Exception Identified",ISERROR(SEARCH("ISSUE:",P36))),"Open - Missing Issue ID",IF(AND(F36="Open",ISERROR(SEARCH("ISSUE:",P36))),"Open - Missing Issue ID",IF(OR(F36="Open",F36="Superseded"),"Open - "&F36&" Issue",IF(AND(E36="Exception Identified",NOT(OR(F36="Adjusted",F36="Passed",F36="Resolved"))),"Open - Undispositioned Exception",IF(OR(G36="Prepared",G36="Reviewed"),"Passed","Open - Unsigned")))))))))) | I36: 20. Verify lead-sheet and reconciliation tie-out formulas foot correctly and the workbook source trail is complete. | J36: Accuracy; Completeness | K36: <.1>/<.2> | O36: AP Controls — all sections | P36: PROC:PROC-AP-AND-ACCRUALS; APCTRL:AP-CYCLE-CONTROLS
I37: Conclusion
A38: Applicable | B38: Required | C38: Not Started | D38: Missing | E38: Unable to Conclude | F38: None | G38: Unsigned | H38: =IF(A38="Not Applicable - Fact Driven",IF(AND(C38="Not Performed",D38="Not Required",OR(F38="None",F38="Resolved",F38="Passed"),OR(G38="Prepared",G38="Reviewed"),LEFT(O38,6)="FACT:/",Q38<>""),"Valid N/A","Blocked"),IF(AND(B38="Recommended",C38="Not Performed",D38="Not Required",OR(F38="None",F38="Resolved",F38="Passed")),"Recommended - Not Performed",IF(C38<>"Performed","Open - "&C38,IF(D38<>"Sufficient","Open - "&D38&" Evidence",IF(E38="Unable to Conclude","Open - Unable to Conclude",IF(AND(E38="Exception Identified",ISERROR(SEARCH("ISSUE:",P38))),"Open - Missing Issue ID",IF(AND(F38="Open",ISERROR(SEARCH("ISSUE:",P38))),"Open - Missing Issue ID",IF(OR(F38="Open",F38="Superseded"),"Open - "&F38&" Issue",IF(AND(E38="Exception Identified",NOT(OR(F38="Adjusted",F38="Passed",F38="Resolved"))),"Open - Undispositioned Exception",IF(OR(G38="Prepared",G38="Reviewed"),"Passed","Open - Unsigned")))))))))) | I38: 21. All planned AP audit procedures above were performed; results support the recorded accounts-payable balance and related disclosures, subject to documented open items. | J38: Overall | K38: <.0>-<.8> | O38: AP Controls — all sections | P38: PROC:PROC-AP-AND-ACCRUALS; APCTRL:AP-CYCLE-CONTROLS

Sheet <.0> Source Index
A1: Source Index
A2: Client / Entity | B2: Vaquite Industries, Inc. | D2: Year-End | E2: 46022 | G2: Currency | H2: USD
A3: Performance Materiality | B3: 23100 | D3: Tolerable misstatement / testing threshold | E3: 20800
A4: Purpose: | B4: Map every AP PBC source and its limitations so the evidence trail is complete and traceable.
A5: Scope: | B5: All client-provided AP support: trade-only AP aging/sub-ledger, GL detail, subsequent disbursement records / bank statements, open/unpaid invoice file, vendor statements, RNI / unmatched-receiving report.
A6: Assertions: | B6: Completeness
A7: Ref | B7: Source document / PBC | C7: Provided by | D7: Date received | E7: Format | F7: Used in tab(s) | G7: Limitations / notes
A21: TM Legends
A22: TB | B22: Agreed to trial balance
A23: GL | B23: Agreed to general ledger
A24: CF | B24: Confirmed with third party
A25: V | B25: Vouched to source document
A26: SR | B26: Agreed to subsequent bank-cleared receipt
A27: R | B27: Recalculated independently
A28: F | B28: Footed / cross-cast
A29: T | B29: Traced to downstream record
A30: PBC | B30: Prepared by client
A32: Before sign-off complete Library Procedure 1 (source completeness & limitations).

Sheet <.1> AP Lead Sheet
A1: AP Lead Sheet
A2: Client / Entity | B2: Vaquite Industries, Inc. | D2: Year-End | E2: 46022 | G2: Currency | H2: USD
A3: Performance Materiality | B3: 23100 | D3: Tolerable misstatement / testing threshold | E3: 20800
A4: Purpose: | B4: Summarize the trade-payable population and tie CY/PY balances to the trial balance and general ledger.
A5: Scope: | B5: Trade payables only (sign convention: positive payable magnitudes). Non-trade items miscoded into the AP aging (e.g. accrued payroll, customer deposits) are excluded and addressed separately.
A6: Assertions: | B6: Completeness; Existence; Rights & Obligations; Accuracy
A7: Entity / Property | B7: GL Account | C7: Account Description | D7: CY TB Balance | E7: PY TB Balance | F7: Difference | G7: % Change | H7: Testing Disposition | I7: Source / Comments
D8: TB | E8: PY | F8: R | G8: R
F9: =IF(AND(D9="",E9=""),"",D9-E9) | G9: =IF(OR(E9="",E9=0),"",(D9-E9)/E9)
F10: =IF(AND(D10="",E10=""),"",D10-E10) | G10: =IF(OR(E10="",E10=0),"",(D10-E10)/E10)
F11: =IF(AND(D11="",E11=""),"",D11-E11) | G11: =IF(OR(E11="",E11=0),"",(D11-E11)/E11)
F12: =IF(AND(D12="",E12=""),"",D12-E12) | G12: =IF(OR(E12="",E12=0),"",(D12-E12)/E12)
F13: =IF(AND(D13="",E13=""),"",D13-E13) | G13: =IF(OR(E13="",E13=0),"",(D13-E13)/E13)
F14: =IF(AND(D14="",E14=""),"",D14-E14) | G14: =IF(OR(E14="",E14=0),"",(D14-E14)/E14)
F15: =IF(AND(D15="",E15=""),"",D15-E15) | G15: =IF(OR(E15="",E15=0),"",(D15-E15)/E15)
F16: =IF(AND(D16="",E16=""),"",D16-E16) | G16: =IF(OR(E16="",E16=0),"",(D16-E16)/E16)
F17: =IF(AND(D17="",E17=""),"",D17-E17) | G17: =IF(OR(E17="",E17=0),"",(D17-E17)/E17)
F18: =IF(AND(D18="",E18=""),"",D18-E18) | G18: =IF(OR(E18="",E18=0),"",(D18-E18)/E18)
A19: Total per lead sheet | D19: =SUM(D9:D18) | E19: =SUM(E9:E18) | F19: =SUM(F9:F18)
A21: Sign convention: payables shown as positive magnitudes. Investigate any debit balances within AP for reclassification to other assets; confirm non-trade items are not commingled in the trade-AP aging.
A23: TM Legends
A24: TB | B24: Agreed to trial balance
A25: GL | B25: Agreed to general ledger
A26: CF | B26: Confirmed with third party
A27: V | B27: Vouched to source document
A28: SR | B28: Agreed to subsequent bank-cleared receipt
A29: R | B29: Recalculated independently
A30: F | B30: Footed / cross-cast
A31: T | B31: Traced to downstream record
A32: PBC | B32: Prepared by client
A34: Before sign-off complete Library Procedures 2-4 (AP Lead Sheet).

Sheet <.2> AP Reconciliation
A1: AP Reconciliation
A2: Client / Entity | B2: Vaquite Industries, Inc. | D2: Year-End | E2: 46022 | G2: Currency | H2: USD
A3: Performance Materiality | B3: 23100 | D3: Tolerable misstatement / testing threshold | E3: 20800
A4: Purpose: | B4: Reconcile the AP sub-ledger / aging to the general ledger and trial balance, and reconcile major vendor statements to the AP sub-ledger.
A5: Scope: | B5: AP sub-ledger / aging, GL detail, trial balance, and vendor statements for major vendors.
A6: Assertions: | B6: Completeness; Existence; Accuracy
A7: A. Sub-ledger to general ledger
A8: AP per sub-ledger / aging
A9: Add/(less): unposted or in-transit invoices
A10: Add/(less): received-not-invoiced (RNI)
A11: Add/(less): other reconciling items
A12: AP per general ledger (computed) | B12: =B8+B9+B10+B11
A13: AP per trial balance
A14: Difference (should be 0) | B14: =B12-B13
A16: B. Vendor statement reconciliations (major vendors)
A17: Vendor | B17: Per statement | C17: Per AP ledger | D17: Difference | E17: Reconciling items | F17: Resolution / comments
D18: =IF(AND(B18="",C18=""),"",B18-C18)
D19: =IF(AND(B19="",C19=""),"",B19-C19)
D20: =IF(AND(B20="",C20=""),"",B20-C20)
D21: =IF(AND(B21="",C21=""),"",B21-C21)
D22: =IF(AND(B22="",C22=""),"",B22-C22)
D23: =IF(AND(B23="",C23=""),"",B23-C23)
D24: =IF(AND(B24="",C24=""),"",B24-C24)
D25: =IF(AND(B25="",C25=""),"",B25-C25)
A27: TM Legends
A28: TB | B28: Agreed to trial balance
A29: GL | B29: Agreed to general ledger
A30: CF | B30: Confirmed with third party
A31: V | B31: Vouched to source document
A32: SR | B32: Agreed to subsequent bank-cleared receipt
A33: R | B33: Recalculated independently
A34: F | B34: Footed / cross-cast
A35: T | B35: Traced to downstream record
A36: PBC | B36: Prepared by client
A38: Before sign-off complete Library Procedures 5-6 (sub-ledger-to-GL reconciliation and vendor statement reconciliations).

Sheet <.3> DPO & SURL Population
A1: DPO & SURL Population
A2: Client / Entity | B2: Vaquite Industries, Inc. | D2: Year-End | E2: 46022 | G2: Currency | H2: USD
A3: Performance Materiality | B3: 23100 | D3: Tolerable misstatement / testing threshold | E3: 20800
A5: Purpose: | B5: Compute Days Payable Outstanding (DPO) and set the SURL look-forward period; quantify the subsequent-disbursement population that selections are drawn from.
A6: Scope: | B6: Expenses paid through disbursements, period-end and prior-period AP/disbursement-related accruals, and the subsequent-disbursement population by type.
A7: Assertions: | B7: Completeness; Cutoff
A9: A. Days Payable Outstanding (DPO) and SURL period
A10: Expenses paid through disbursements (A) | B10: [Enter CY purchases / relevant disbursement expense] | C10: [Cite complete CY numerator population]
A11: Period-end AP & disbursement-related accruals (B) | B11: [Enter CY ending AP and related accrual amount] | C11: [Cite CY AP / accrual source]
A12: Prior-period AP & disbursement-related accruals (B) | B12: [Enter PY ending AP and related accrual amount] | C12: [Cite PY AP / accrual source]
A13: Average AP | B13: =IF(COUNT(B11:B12)<2,"",(B11+B12)/2)
A14: AP turnover | B14: =IF(OR(NOT(ISNUMBER(B10)),NOT(ISNUMBER(B13)),B13=0),"",B10/B13)
A15: Days Payable Outstanding (DPO) | B15: =IF(OR(NOT(ISNUMBER(B14)),B14=0),"",365/B14)
A16: SURL start date (period-end + 1) | B16: =IF(ISNUMBER(E2),E2+1,"")
A17: SURL end date (= start + DPO) | B17: =IF(OR(NOT(ISNUMBER(B16)),NOT(ISNUMBER(B15))),"",B16+ROUNDUP(B15,0))
A19: B. Subsequent-disbursement population
A20: Disbursement type | B20: Amount
A21: Checks
A22: ACH
A23: Wires
A24: Credit card
A25: Other
A26: Total disbursement population | B26: =SUM(B21:B25)
A28: SURL selections are made from this disbursement population (above the testing threshold, through the SURL end date) OR directly from the bank statement. If selections are made from the bank statement, the completeness test on <.5> is NOT required.
A30: TM Legends
A31: TB | B31: Agreed to trial balance
A32: GL | B32: Agreed to general ledger
A33: CF | B33: Confirmed with third party
A34: V | B34: Vouched to source document
A35: SR | B35: Agreed to subsequent bank-cleared receipt
A36: R | B36: Recalculated independently
A37: F | B37: Footed / cross-cast
A38: T | B38: Traced to downstream record
A39: PBC | B39: Prepared by client
A41: Before sign-off complete Library Procedures 7-8 (DPO-based period and population).

Sheet <.4> SURL Subsequent Disb
A1: Search for Unrecorded Liabilities — Subsequent Disbursements
A2: Client / Entity | B2: Vaquite Industries, Inc. | D2: Year-End | E2: 46022 | G2: Currency | H2: USD
A3: Performance Materiality | B3: 23100 | D3: Tolerable misstatement / testing threshold | E3: 20800
A4: Purpose: | B4: Examine subsequent disbursements above the testing threshold through the SURL period; vouch to invoice, determine the goods/service period, and classify the cutoff outcome at period end.
A5: Scope: | B5: Selections from the subsequent-disbursement population (<.3>) or bank statement, above the testing threshold, through the SURL end date.
A6: Assertions: | B6: Completeness; Cutoff; Valuation & Allocation
A7: Sample # | B7: Payment ref # | C7: Payment date | D7: Vendor | E7: Payment amount | F7: Invoice # | G7: Invoice date | H7: Invoice amount | I7: Goods received / service period | J7: Relates to (pre-YE / post-YE) | K7: In YE AP? (Y/N) | L7: Properly included @ PE | M7: Properly excluded @ PE | N7: Improperly included @ PE | O7: Improperly excluded (unrecorded liab.) | P7: GL account | Q7: Tie-back / AP ref | R7: Notes
E8: V | H8: V | O8: R
A30: Total | E30: =SUM(E9:E29) | L30: =SUM(L9:L29) | M30: =SUM(M9:M29) | N30: =SUM(N9:N29) | O30: =SUM(O9:O29)
A32: For each item determine the period the goods/services relate to: if PRE-year-end, the liability belongs in year-end AP (tie back to the AP listing; an 'improperly excluded' item is an unrecorded liability); if POST-year-end, confirm it is properly excluded from year-end AP. Payment amount should reconcile to the included/excluded classification columns.
A34: TM Legends
A35: TB | B35: Agreed to trial balance
A36: GL | B36: Agreed to general ledger
A37: CF | B37: Confirmed with third party
A38: V | B38: Vouched to source document
A39: SR | B39: Agreed to subsequent bank-cleared receipt
A40: R | B40: Recalculated independently
A41: F | B41: Footed / cross-cast
A42: T | B42: Traced to downstream record
A43: PBC | B43: Prepared by client
A45: Before sign-off complete Library Procedures 9-10 (SURL examination and cutoff classification).

Sheet <.5> Completeness of Disb
A1: Completeness of Disbursements (conditional)
A2: Client / Entity | B2: Vaquite Industries, Inc. | D2: Year-End | E2: 46022 | G2: Currency | H2: USD
A3: Performance Materiality | B3: 23100 | D3: Tolerable misstatement / testing threshold | E3: 20800
A4: Purpose: | B4: Test the completeness of the disbursement population from which SURL selections were made. Required ONLY if selections were drawn from the disbursement listing; NOT required if drawn from the bank statement.
A5: Scope: | B5: The subsequent-disbursement listing and the corresponding subsequent-period bank statement.
A6: Assertions: | B6: Completeness
A7: SURL selection source | B7: [Disbursement listing / Bank statement]
A8: If 'Bank statement' — completeness test below is NOT required (the bank statement is inherently complete). Document and skip.
A10: A. Sequence check of payment / check document numbers
A11: Item | B11: Result | C11: Reference | D11: Comments
A12: First document number in sequence
A13: Last document number in sequence
A14: Missing / voided numbers (list)
A15: Gaps investigated & explained (Y/N)
A17: B. Reconcile disbursement listing to subsequent-period bank statement
A18: Total per disbursement listing
A19: Total per bank statement (subsequent period)
A20: Difference | B20: =IF(AND(B18="",B19=""),"",B18-B19)
A21: Reconciling items (describe)
A24: TM Legends
A25: TB | B25: Agreed to trial balance
A26: GL | B26: Agreed to general ledger
A27: CF | B27: Confirmed with third party
A28: V | B28: Vouched to source document
A29: SR | B29: Agreed to subsequent bank-cleared receipt
A30: R | B30: Recalculated independently
A31: F | B31: Footed / cross-cast
A32: T | B32: Traced to downstream record
A33: PBC | B33: Prepared by client
A35: Before sign-off complete Library Procedures 11-12 (completeness via sequence check / bank-statement reconciliation; document when not required).

Sheet <.6> Outstanding Checks
A1: Outstanding Checks → AP Tie-Back
A2: Client / Entity | B2: Vaquite Industries, Inc. | D2: Year-End | E2: 46022 | G2: Currency | H2: USD
A3: Performance Materiality | B3: 23100 | D3: Tolerable misstatement / testing threshold | E3: 20800
A4: Purpose: | B4: Select outstanding checks issued on or before period-end that had not cleared the bank, and tie each back to the AP listing to confirm the related payable is appropriately recorded.
A5: Scope: | B5: Year-end outstanding-check list (checks not yet reflected in the bank) and the AP sub-ledger / listing.
A6: Assertions: | B6: Completeness; Existence
A7: Check # | B7: Payee / Vendor | C7: Check date | D7: Amount | E7: Cleared per subsequent bank (date) | F7: Still outstanding (Y/N) | G7: Per AP listing (Y/N) | H7: AP / invoice ref | I7: Agreed (Y/N) | J7: Comments
D8: V | E8: T | G8: T
A23: Total | D23: =SUM(D9:D22)
A25: Outstanding checks reduce both cash and AP when issued; select uncleared checks and trace to the AP listing to confirm the payable was recorded/relieved appropriately and AP is neither over- nor under-stated.
A27: TM Legends
A28: TB | B28: Agreed to trial balance
A29: GL | B29: Agreed to general ledger
A30: CF | B30: Confirmed with third party
A31: V | B31: Vouched to source document
A32: SR | B32: Agreed to subsequent bank-cleared receipt
A33: R | B33: Recalculated independently
A34: F | B34: Footed / cross-cast
A35: T | B35: Traced to downstream record
A36: PBC | B36: Prepared by client
A38: Before sign-off complete Library Procedure 13 (outstanding checks tie-back).

Sheet <.7> Open Invoice & Cutoff
A1: Open / Unpaid Invoice & Cutoff
A2: Client / Entity | B2: Vaquite Industries, Inc. | D2: Year-End | E2: 46022 | G2: Currency | H2: USD
A3: Performance Materiality | B3: 23100 | D3: Tolerable misstatement / testing threshold | E3: 20800
A4: Purpose: | B4: Select unpaid / open invoices from the subsequent period; determine the goods/service period; if pre-year-end, tie back to year-end AP (an unrecorded liability if omitted); if post-year-end, confirm exclusion from year-end AP.
A5: Scope: | B5: Subsequent-period open / unpaid invoice file and the received-not-invoiced (RNI) / unmatched-receiving report.
A6: Assertions: | B6: Completeness; Existence; Cutoff
A7: Sample # | B7: Vendor | C7: Invoice # | D7: Invoice date | E7: Due / aging date | F7: Invoice amount | G7: Goods received / service period | H7: Relates to (pre-YE / post-YE) | I7: Should be in YE AP? (Y/N) | J7: In YE AP? (Y/N) | K7: Tie-back / AP ref | L7: Exception amount | M7: Conclusion / Comments
F8: V | L8: R
L9: =IF(OR(AND(I9="Y",J9="N"),AND(I9="N",J9="Y")),F9,0)
L10: =IF(OR(AND(I10="Y",J10="N"),AND(I10="N",J10="Y")),F10,0)
L11: =IF(OR(AND(I11="Y",J11="N"),AND(I11="N",J11="Y")),F11,0)
L12: =IF(OR(AND(I12="Y",J12="N"),AND(I12="N",J12="Y")),F12,0)
L13: =IF(OR(AND(I13="Y",J13="N"),AND(I13="N",J13="Y")),F13,0)
L14: =IF(OR(AND(I14="Y",J14="N"),AND(I14="N",J14="Y")),F14,0)
L15: =IF(OR(AND(I15="Y",J15="N"),AND(I15="N",J15="Y")),F15,0)
L16: =IF(OR(AND(I16="Y",J16="N"),AND(I16="N",J16="Y")),F16,0)
L17: =IF(OR(AND(I17="Y",J17="N"),AND(I17="N",J17="Y")),F17,0)
L18: =IF(OR(AND(I18="Y",J18="N"),AND(I18="N",J18="Y")),F18,0)
L19: =IF(OR(AND(I19="Y",J19="N"),AND(I19="N",J19="Y")),F19,0)
L20: =IF(OR(AND(I20="Y",J20="N"),AND(I20="N",J20="Y")),F20,0)
... L29: =IF(OR(AND(I29="Y",J29="N"),AND(I29="N",J29="Y")),F29,0)
A30: Total | F30: =SUM(F9:F29) | L30: =SUM(L9:L29)
A32: Exception amount auto-flags a mismatch: an invoice that SHOULD be in year-end AP but is not (an unrecorded liability), or one that should NOT be but is. Also obtain the RNI / unmatched-receiving report to test completeness of accrued purchases.
A34: TM Legends
A35: TB | B35: Agreed to trial balance
A36: GL | B36: Agreed to general ledger
A37: CF | B37: Confirmed with third party
A38: V | B38: Vouched to source document
A39: SR | B39: Agreed to subsequent bank-cleared receipt
A40: R | B40: Recalculated independently
A41: F | B41: Footed / cross-cast
A42: T | B42: Traced to downstream record
A43: PBC | B43: Prepared by client
A45: Before sign-off complete Library Procedures 14-15 (open-invoice cutoff and RNI completeness).

Sheet <.8> Ratios & Disclosures
A1: Ratios & Disclosures
A2: Client / Entity | B2: Vaquite Industries, Inc. | D2: Year-End | E2: 46022 | G2: Currency | H2: USD
A3: Performance Materiality | B3: 23100 | D3: Tolerable misstatement / testing threshold | E3: 20800
A4: Purpose: | B4: Compute AP analytics and evaluate presentation and disclosure matters.
A5: Scope: | B5: Lead-sheet, reconciliation and SURL results; COGS / expenses and prior-year data for ratios.
A6: Assertions: | B6: Presentation & Disclosure; Classification
A7: A. Analytics
A8: Metric | B8: CY | C8: PY / Comparator | D8: Change | E8: Note
A9: Days payable outstanding (DPO) | B9: =IF(ISNUMBER('<.3> DPO & SURL Population'!B15),'<.3> DPO & SURL Population'!B15,"N/A") | C9: =IF(AND(ISNUMBER(C10),C10<>0),365/C10,"N/A") | D9: =IF(AND(ISNUMBER(B9),ISNUMBER(C9)),B9-C9,"") | E9: DPO = 365 / AP turnover; PY uses the same basis or N/A.
A10: AP turnover | B10: =IF(ISNUMBER('<.3> DPO & SURL Population'!B14),'<.3> DPO & SURL Population'!B14,"N/A") | C10: =IF(AND(ISNUMBER(WP_AP_METRIC_PY_PURCHASES),ISNUMBER(WP_AP_METRIC_PY_AVERAGE_TRADE_AP),WP_AP_METRIC_PY_AVERAGE_TRADE_AP<>0),WP_AP_METRIC_PY_PURCHASES/WP_AP_METRIC_PY_AVERAGE_TRADE_AP,"N/A") | D10: =IF(AND(ISNUMBER(B10),ISNUMBER(C10)),B10-C10,"") | E10: Turnover uses purchases/relevant expense divided by average AP.
A11: AP as % of COGS / expenses | B11: =IF(AND(COUNT('<.1> AP Lead Sheet'!D9:D18)>0,ISNUMBER(WP_AP_METRIC_CY_RELEVANT_EXPENSE),WP_AP_METRIC_CY_RELEVANT_EXPENSE<>0),'<.1> AP Lead Sheet'!D19/WP_AP_METRIC_CY_RELEVANT_EXPENSE,"N/A") | C11: =IF(AND(COUNT('<.1> AP Lead Sheet'!E9:E18)>0,ISNUMBER(WP_AP_METRIC_PY_RELEVANT_EXPENSE),WP_AP_METRIC_PY_RELEVANT_EXPENSE<>0),'<.1> AP Lead Sheet'!E19/WP_AP_METRIC_PY_RELEVANT_EXPENSE,"N/A") | D11: =IF(AND(ISNUMBER(B11),ISNUMBER(C11)),B11-C11,"") | E11: CY/PY relevant-expense denominators must use the same scope.
A12: Trade AP balance | B12: =IF(COUNT('<.1> AP Lead Sheet'!D9:D18)>0,'<.1> AP Lead Sheet'!D19,"N/A") | C12: =IF(COUNT('<.1> AP Lead Sheet'!E9:E18)>0,'<.1> AP Lead Sheet'!E19,"N/A") | D12: =IF(AND(ISNUMBER(B12),ISNUMBER(C12)),B12-C12,"") | E12: Trade AP only; unavailable PY evidence is N/A, not zero.
A13: AP days vs supplier terms | B13: =B9 | C13: =IF(ISNUMBER(WP_AP_METRIC_WEIGHTED_SUPPLIER_TERMS),WP_AP_METRIC_WEIGHTED_SUPPLIER_TERMS,"N/A") | D13: =IF(AND(ISNUMBER(B13),ISNUMBER(C13)),B13-C13,"") | E13: Column C is the amount-weighted contractual supplier-term comparator, not PY and not actual payment lag.
A15: B. Disclosure matters
A16: Area | B16: Relevant? (Y/N) | C16: Support / source | D16: Conclusion | E16: Comments
A17: Related-party / affiliate payables
A18: Current vs noncurrent classification
A19: Debit balances in AP reclassified to assets
A20: Customer deposits / contract liabilities classification
A21: Concentration of payables
A22: Commitments / purchase obligations
A24: TM Legends
A25: TB | B25: Agreed to trial balance
A26: GL | B26: Agreed to general ledger
A27: CF | B27: Confirmed with third party
A28: V | B28: Vouched to source document
A29: SR | B29: Agreed to subsequent bank-cleared receipt
A30: R | B30: Recalculated independently
A31: F | B31: Footed / cross-cast
A32: T | B32: Traced to downstream record
A33: PBC | B33: Prepared by client
A35: Before sign-off complete Library Procedures 16-18 (analytics, presentation & disclosure, commitments/unrecorded obligations).

Sheet Planning Context
A1: AUTHORITATIVE PLANNING CONTEXT
A2: Field | B2: Value
A3: Entity Name | B3: Vaquite Industries, Inc.
A4: Financial Statement Date | B4: 46022
A5: Reporting Currency | B5: USD
A6: Overall Materiality | B6: 30700
A7: Performance Materiality | B7: 23100
A8: Tolerable Misstatement | B8: 20800
A9: Individually Significant Threshold | B9: 11600
A10: Posting Threshold | B10: 1000
A11: Clearly Trivial Threshold | B11: 1000
A12: Analytical Precision | B12: 20800
A14: Bound planning records | B14: Canonical IDs
A15: Sampling plan ID | B15: SAMPLE-AP-AND-ACCRUALS
A16: Selection IDs | B16: PROC-AP-VOUCHING:PREPAID-Invoice reference Ppd 001; PROC-AP-VOUCHING:Vendor reference Invoice Stk 0033; PROC-AP-VOUCHING:Vendor reference Invoice Stk 0039; PROC-AP-VOUCHING:Vendor reference Invoice Stk 0027; PROC-AP-VOUCHING:Vendor reference Invoice Stk 0021; PROC-AP-VOUCHING:Vendor reference Invoice Stk 0015; PROC-AP-VOUCHING:Vendor reference Invoice Stk 0009; PROC-AP-VOUCHING:Vendor reference Invoice Stk 0003; PROC-AP-VOUCHING:Vendor reference Invoice Stk 0054; PROC-AP-VOUCHING:Vendor reference Invoice Stk 0062; PROC-AP-VOUCHING:Vendor reference Invoice Stk 0030; PROC-AP-VOUCHING:Vendor reference Invoice Stk 0007; PROC-AP-VOUCHING:Vendor reference Invoice Stk 0024; PROC-AP-VOUCHING:Vendor reference Invoice Stk 0001; PROC-AP-VOUCHING:Vendor reference Invoice Stk 0065; PROC-AP-VOUCHING:Vendor reference Invoice Stk 0053; PROC-AP-VOUCHING:Vendor reference Invoice Stk 0058; PROC-AP-VOUCHING:Vendor reference Invoice Stk 0055; PROC-AP-VOUCHING:Vendor reference Invoice Stk 0004; PROC-AP-VOUCHING:Vendor reference Invoice Stk 0008; PROC-AP-VOUCHING:Vendor reference Invoice Stk 0056; PROC-ACCRUALS-DETAIL:Accrual reference RNI 01
A17: Selection requirements | B17: qualitative mandatory items; individually significant items
A18: Procedure IDs | B18: PROC-AP-AND-ACCRUALS
A19: Procedure window IDs | B19: WIN-AP-SURL
A20: Significant-risk response IDs
A21: Audit team assignments | B21: preparer: Audit Senior 80A0; reviewer: Audit Manager 403F

Sheet AP Controls
A1: ACCOUNTS PAYABLE — FSM EXECUTION CONTROLS
A2: These controls do not replace audit work. They prevent registered selections, mandatory vendor-statement scope, AP-direction testing, and typed metric/window requirements from being silently discarded.
A4: A. REGISTERED SELECTION EXECUTION RECONCILIATION
A5: Procedure ID | B5: PROC-AP-VOUCHING | C5: Sampling plan ID | D5: SAMPLE-AP-AND-ACCRUALS | E5: Population hash | F5: 618808e7b991d654ab10742177ae785836cb86e3027c450cff5fd80aab2d73b6
A6: Registered selections | B6: 21 | C6: Targeted / key | D6: 8 | E6: Seeded residual | F6: 13
A7: Invariant | B7: Each registered ID must resolve to one exact result row, or to an approved equivalent deviation that identifies approval, rationale, replacement IDs, and equivalent-or-greater objective coverage.
A8: Registered Selection ID | B8: Selection Reason | C8: Planned Amount | D8: Secondary Reasons | E8: Execution Disposition | F8: Exact Workpaper Result Ref | G8: Approved Deviation ID | H8: Deviation Rationale | I8: Equivalent Selection IDs / Coverage | J8: Reconciliation Status
A9: PREPAID-Invoice reference Ppd 001 | B9: procedure_specific_key_item | C9: 26000 | E9: [Select tested or approved deviation] | F9: [Enter exact result row / reference] | G9: [Enter approved deviation ID or N/A] | H9: [Enter deviation rationale or N/A] | I9: [Enter equivalent selection IDs and coverage or N/A] | J9: =IF(OR(AND(E9="Tested as registered",AND(F9<>"",LEFT(F9,1)<>"[")),AND(E9="Approved equivalent deviation",AND(F9<>"",LEFT(F9,1)<>"["),AND(G9<>"",LEFT(G9,1)<>"["),G9<>"N/A",AND(H9<>"",LEFT(H9,1)<>"["),H9<>"N/A",AND(I9<>"",LEFT(I9,1)<>"["),I9<>"N/A")),"Reconciled","Open")
A10: Vendor reference Invoice Stk 0033 | B10: procedure_specific_key_item | C10: 24759.57 | E10: [Select tested or approved deviation] | F10: [Enter exact result row / reference] | G10: [Enter approved deviation ID or N/A] | H10: [Enter deviation rationale or N/A] | I10: [Enter equivalent selection IDs and coverage or N/A] | J10: =IF(OR(AND(E10="Tested as registered",AND(F10<>"",LEFT(F10,1)<>"[")),AND(E10="Approved equivalent deviation",AND(F10<>"",LEFT(F10,1)<>"["),AND(G10<>"",LEFT(G10,1)<>"["),G10<>"N/A",AND(H10<>"",LEFT(H10,1)<>"["),H10<>"N/A",AND(I10<>"",LEFT(I10,1)<>"["),I10<>"N/A")),"Reconciled","Open")
A11: Vendor reference Invoice Stk 0039 | B11: procedure_specific_key_item | C11: 24759.57 | E11: [Select tested or approved deviation] | F11: [Enter exact result row / reference] | G11: [Enter approved deviation ID or N/A] | H11: [Enter deviation rationale or N/A] | I11: [Enter equivalent selection IDs and coverage or N/A] | J11: =IF(OR(AND(E11="Tested as registered",AND(F11<>"",LEFT(F11,1)<>"[")),AND(E11="Approved equivalent deviation",AND(F11<>"",LEFT(F11,1)<>"["),AND(G11<>"",LEFT(G11,1)<>"["),G11<>"N/A",AND(H11<>"",LEFT(H11,1)<>"["),H11<>"N/A",AND(I11<>"",LEFT(I11,1)<>"["),I11<>"N/A")),"Reconciled","Open")
A12: Vendor reference Invoice Stk 0027 | B12: procedure_specific_key_item | C12: 24514.43 | E12: [Select tested or approved deviation] | F12: [Enter exact result row / reference] | G12: [Enter approved deviation ID or N/A] | H12: [Enter deviation rationale or N/A] | I12: [Enter equivalent selection IDs and coverage or N/A] | J12: =IF(OR(AND(E12="Tested as registered",AND(F12<>"",LEFT(F12,1)<>"[")),AND(E12="Approved equivalent deviation",AND(F12<>"",LEFT(F12,1)<>"["),AND(G12<>"",LEFT(G12,1)<>"["),G12<>"N/A",AND(H12<>"",LEFT(H12,1)<>"["),H12<>"N/A",AND(I12<>"",LEFT(I12,1)<>"["),I12<>"N/A")),"Reconciled","Open")
